Workbook

Sheet Overview
A1: Twenty-Five Untapped Opportunities
A2: Research date: 2 August 2026 · 15 discovery lenses · 172 raw candidates · 77 distinct opportunities · 25 selected
A4: READ THIS FIRST
A5: The session's 200-call web-search budget was exhausted partway through this study.
A6: Every finding carries an evidence tier recording what its competitor check was actually worth.
A7: The adversarial verification pass ran with ZERO live searches, so its objections are recorded as open
A8: diligence questions, never as verdicts. The planned "refuted by both lenses = disqualified" rule was
A9: abandoned for that reason - applying it would have deleted the pool on an unusable measurement.
A11: The tier rates the COMPETITOR CHECK, not the discovery. The scout stage ran 41-84 live queries per lens
A12: before the budget died, so the "why now" triggers generally rest on real search results. On a Recall-only
A13: finding, trust the trigger considerably more than the claim that the space is empty.
A15: Evidence tiers
A16: Tier | B16: In top 25 | C16: In full pool | D16: Meaning
A17: Search-backed | B17: =COUNTIF('Top 25'!$E:$E,$A17) | C17: =COUNTIF('Screening Scores'!$C:$C,$A17) | D17: Crowding checked with roughly 30 live competitor queries
A18: Thin | B18: =COUNTIF('Top 25'!$E:$E,$A18) | C18: =COUNTIF('Screening Scores'!$C:$C,$A18) | D18: Only 2-3 live queries before the search budget ran out
A19: Recall-only | B19: =COUNTIF('Top 25'!$E:$E,$A19) | C19: =COUNTIF('Screening Scores'!$C:$C,$A19) | D19: No live crowding search; competitors named from model recall
A20: Total | B20: =SUM(B17:B19) | C20: =SUM(C17:C19)
A22: Scoring weights | B22: Edit the yellow cells to re-rank the whole workbook
A23: Dimension | B23: Weight | C23: Meaning of a 10
A24: Overlooked | B24: 0.28 | C24: Essentially nobody is building this, verified by search
A25: Inflection (3-5 yr) | B25: 0.24 | C25: Near-certain to be a large market by 2029-2031
A26: Buildable today | B26: 0.2 | C26: A 1-3 person team ships a real wedge in 90 days
A27: Market size | B27: 0.16 | C27: Multi-billion addressable
A28: Defensibility | B28: 0.12 | C28: Strong compounding moat
A29: Total | B29: =SUM(B24:B28) | C29: Must equal 1.00
A31: Sheets in this workbook
A32: Top 25 | B32: The ranked selection, with scores, evidence tier and selection rationale
A33: All Opportunities | B33: All 77 distinct opportunities that survived de-duplication
A34: Screening Scores | B34: Every screening score, competitor check and kill risk
A35: Verification | B35: Adversarial objections - open questions, not verdicts
A36: Honorable Mentions | B36: The 12 that just missed the cut
A38: Source: research/dataset.json in this repository; see research/METHODOLOGY.md for the full pipeline and coverage limitations. Composite scores on every sheet are live formulas driven by the yellow weight cells above, so changing a weight re-scores all 77 opportunities at once. Data note: one screening agent recorded a composite of 4.92 for "rec-e-invoicing-mandate-plumbing-for-us-mid-market-erps" where the stated weights give 4.64. The workbook computes every composite from the weights, so it shows the corrected 4.64. That opportunity was not in the top 25, so the selection is unaffected. All 76 other composites reproduce exactly. Build note: LibreOffice is non-functional in the environment that produced this file, so formulas were written without cached values and could not be machine-recalculated. Recalculate-on-load is set, and every formula uses only SUM, ROUND, COUNTIF, INDEX, MATCH and IFERROR. If any cell looks blank, press Ctrl-Alt-F9.

Sheet Top 25
A1: Rank | B1: Opportunity | C1: Category | D1: ID | E1: Evidence | F1: Overlooked | G1: Inflection | H1: Buildable | I1: Market | J1: Defensibility | K1: Composite | L1: The wedge | M1: Why this rank | N1: What kills it | O1: Open questions from adversarial review
A2: 1 | B2: Ride-through models and curtailment proof for NERC-registered data centers | C2: Physical / industrial | D2: datacenter-as-grid-entity-compliance | E2: Recall-only | F2: 5 | G2: 8 | H2: 7 | I2: 6 | J2: 5 | K2: =ROUND(F2*Overview!$B$24+G2*Overview!$B$25+H2*Overview!$B$26+I2*Overview!$B$27+J2*Overview!$B$28,2) | L2: Boutique that builds the filed dynamic model (EPRI UDM/CMLD), runs disturbance-response testing on UPS/rectifier/chiller settings, and assembles the NERC attestation package per campus at $150k-$600k, plus the signed metering record proving each ERCOT curtailment. | M2: Best risk-adjusted bet in the pool: four dated triggers have ALREADY fired (NERC Level 3 Alert 4 May 2026 with responses due 3 Aug 2026 — literally this week; FERC RD26-7 ordering mandatory computational-load standards by 31 Dec 2026; RM26-4 §206 orders to every RTO 18 Jun 2026), so revenue exists in month one rather than after a rule lands. No license gate, no capital, no enterprise sales cycle — the buyer is under an enforcement clock. Two or three power-systems engineers can start Monday. Re-validation after every trip event makes it recurring, and ERCOT PCLR registration is a second product on the same relationship. Overlooked only scored 5 because Certrec, 1898 & Co and Burns & McDonnell can pivot — but those firms are capacity-constrained and the specific artifact (validated EMT models for power-electronic compute load) is new to everyone, so the head start is real. Ranked above nuclear and customs because it needs no exam, no ACE certification, and no three-year audit history before the first invoice. | N2: It is a boutique engineering consultancy, not a compounding software company. The binding constraint is one or two humans who can translate IEC 62040-3 UPS transfer behavior into an ISO-acceptable load model, and those people are the scarcest labor in the sector — Burns & McDonnell, Certrec and POWER already hold the hyperscaler relationships and can hire them away or simply out-bench you. Revenue scales linearly with headcount, the 'reusable model library' is mostly customer-confidential, and the natural exit is acquisition by an EPC at services multiples rather than a durable platform. | O2: Not selected for verification
A3: 2 | B3: Entry Type 13 and instrument-aware duty recovery for the post-de-minimis long tail | C3: Regulatory clock | D3: long-tail-customs-entry-and-duty-recovery | E3: Recall-only | F3: 4 | G3: 8 | H3: 6 | I3: 8 | J3: 6 | K3: =ROUND(F3*Overview!$B$24+G3*Overview!$B$25+H3*Overview!$B$26+I3*Overview!$B$27+J3*Overview!$B$28,2) | L3: Software letting one licensed broker supervise 50-100x entry throughput on low-value shipments, sold as entry-as-a-service to SMB importers, bolted to instrument-aware drawback recovery (Section 301 eligible, Section 232 generally not). | M3: The only genuine compounding regulatory moat in the entire 77: a licensed profession with exam-gated supply (12-22% pass rate) meeting a legislated ~100x volume shock (1.36B FY2024 de minimis parcels), where the license, the bond and the accumulated per-SKU ruling corpus all compound and none can be cloned by a software competitor. The statutory spine is the hardest in the pool — OBBBA permanently repeals the commercial de minimis statute effective 1 Jul 2027, which no executive action reverses — and the duty-recovery half is the single most credible 'LLMs newly make this cheap' claim here because it is legal-grade reasoning over structured data with a dollar-denominated output. Ranked 2 not 1 on two real drags: ACE/ABI certification is a 6-12 month regulatory slog outside the 90-day frame, and Zonos (~$69M, already licensed and filing automated low-value entries) can move down-market faster than a new entrant acquires the tail. Entry Type 13 and the 22 Sep 2026 ACE test are unverified and load-bearing — diligence before capital. | N3: Unit economics on the exact segment being targeted. A $500 shipment cannot carry compliant entry work at any price — that is why 3PLs are turning these accounts away, and software does not repeal it; at $15/entry you need enormous volume before you cover the classification labor, while carrying 19 CFR 111 broker penalty and license exposure on SKUs you have never seen. Meanwhile the parcel carriers (DHL, UPS, FedEx) own the flow and built their own de minimis replacement entry services, and Zonos can move down-market faster than you can acquire the long tail. Secondary risk: the ACE ABI certification gate is a 6-12 month regulatory slog, not part of a 90-day plan. Offsetting all this, and why this one advances — a licensed profession with a hard exam-gated supply constraint meeting a legislated ~100x volume shock is a genuine dislocation, the license plus bond plus accumulated per-SKU ruling corpus is the only real compounding regulatory moat in this batch, and instrument-aware planning is the single most credible 'LLMs newly make this cheap' argument here because it is legal-grade reasoning over structured data with a dollar-denominated output. | O3: Not selected for verification
A4: 3 | B4: NQA-1 qualification and commercial grade dedication as a service | C4: Physical / industrial | D4: nuclear-naval-supplier-qualification | E4: Recall-only | F4: 6 | G4: 7 | H4: 8 | I4: 5 | J4: 6 | K4: =ROUND(F4*Overview!$B$24+G4*Overview!$B$25+H4*Overview!$B$26+I4*Overview!$B$27+J4*Overview!$B$28,2) | L4: Fixed-fee turnkey installation of an Appendix B / NQA-1 quality system into existing AS9100 shops, plus an outsourced dedicating-entity service with a structured critical-characteristics library for commercial grade dedication. | M4: Highest round-1 composite (6.48) and the bottleneck is correctly identified: qualification, not capital or reactor design, gates both the nuclear build-out and the submarine industrial base, and NUPIC is a closed utility club new entrants structurally cannot join. Demand broke the chicken-and-egg deadlock in 2025-2026 via hyperscaler PPAs and the ADVANCE Act, and the 17,000-to-~5,000 submarine supplier contraction plus BlueForge's ~$950M NAVSEA award are real. Held to 3 by the screener's correct kill: this is a consulting business wearing software clothes. Critical characteristics are treated as proprietary and litigation-sensitive, so the cross-buyer reusable library — the entire software thesis — may never accrete, leaving hourly-consulting margins against Curtiss-Wright/Scientech and Paragon, who already operate as third-party dedicating entities with audit histories you would spend three years earning. Still advances because even the consulting version is a real, defensible, high-margin business against a hard supply constraint. | N4: It is a consulting business wearing software clothes. CGD packages are bespoke and liability-bearing, and utilities, reactor developers and their suppliers treat critical characteristics as proprietary and litigation-sensitive — so the cross-buyer reusable library never accretes, margins stay at hourly-consulting levels, and Curtiss-Wright or Paragon bolt a workflow tool onto a book of business and a dedicating-entity audit history you spent three years earning. | O4: Not selected for verification
A5: 4 | B5: PFAS-Compliant Biosolids Outlet Exchange for the Mid-Atlantic | C5: Physical / industrial | D5: biosolids-outlet-exchange | E5: Search-backed | F5: 5 | G5: 7 | H5: 8 | I5: 5 | J5: 4 | K5: =ROUND(F5*Overview!$B$24+G5*Overview!$B$25+H5*Overview!$B$26+I5*Overview!$B$27+J5*Overview!$B$28,2) | L5: Regional brokerage contracting landfill airspace, thermal destruction slots and compliant out-of-state farmland, matched against each POTW's tonnage and PFAS test results at a firm per-wet-ton price with documentation attached; second product is upstream industrial source control. | M5: Survived adversarial verification 1-of-2, and the surviving lens confirmed the strongest-verified trigger in its batch: Maryland SB 719 signed 28 April 2026 banning land application at or above 50 ppb PFOA/PFOS from 1 Oct 2028, a 25-50 ppb restricted tier, plus Maine, Connecticut and six 2026 enactments and EPA's 1 July 2026 draft guidance. Crucially the mechanism already ran once for real — Maine's LD 1911 produced exactly the predicted out-of-state trucking and tipping-cost spike — so this is not a forecast. Capital-light, no capex, and the buyer is a rate-funded public utility that must move wet tons daily and has clear procurement authority. Ranked 4 rather than higher because the refuting lens is right that Synagro (Goldman-backed) and Denali (PE-backed) hold long-term contracts, bonding and the trucks, and municipal RFPs demand performance bonds and referenceable tonnage a two-person broker lacks; PFAS liability on land application is also increasingly uninsurable. Wedge in as the analyst who knows which outlet accepts which concentration this quarter, then earn the tonnage. | N5: Defensibility is the weak leg: non-exclusive outlet contracts, zero capex, and no proprietary data mean Synagro or Denali can match any quoted per-wet-ton price and bundle the hauling you do not own. The 'knowing which outlet accepts which concentration this quarter' edge is a decaying asset — once state thresholds stabilize (MD's are already written into statute with numbers), the arbitrage compresses. Landfill airspace is the substitution risk in the other direction: Maryland/Maine reporting already flags landfill capacity concerns, so the outlets you forward-contract may themselves be closed to biosolids by state action. Market size is modest — US biosolids management is single-digit billions of total spend and a Mid-Atlantic broker's take rate is a thin slice of that. Working capital risk if you sign firm per-ton prices against outlet costs that reprice. | O5: [lens] The 'regional biosolids outlet brokerage' is the existing business model of large, capitalized, vertically integrated incumbents — Synagro (the largest US biosolids manager, Goldman Sachs Infrastructure-owned), Denali Water Solutions (TPG-backed), and Merrell Bros. — who already contract POTW tonnage, own or contract landfill/incineration/land-application outlets, run the trucks, and have been selling PFAS-transition planning as their headline service since the EPA risk assessment. The regulatory-analysis layer ('which outlet accepts which concentration under which state rule this quarter') is the core 2025-2026 consulting product of Brown and Caldwell, Hazen and Sawyer, Arcadis, CDM Smith, Black & Veatch and Stantec, all of whom run biosolids master-planning practices. A two-person no-capex broker has neither outlet access nor bonding nor the balance sheet to offer a firm per-wet-ton price. [lens] Not the trigger — the trigger holds — but the seat at the table. This market is already consolidated and contracted: Synagro (the largest US biosolids manager, Goldman Sachs West Street-backed), Casella Organics (which does precisely regional POTW outlet brokerage across New England and the Mid-Atlantic, including absorbing Maine's post-ban volume), Denali Water Solutions, Merrell Bros., Quantix and the landfill majors already hold the landfill airspace, the dryers, the incinerator slots and the multi-year municipal contracts. 'Two operators, no capital equipment' cannot sign non-exclusive outlet capacity that the incumbents have under long-term take-or-pay, and cannot win the POTW side either: municipal biosolids hauling is procured by public RFP requiring performance bonds, insurance minimums, state hauler/land-application permits and referenceable tonnage history. The PFAS liability exposure is the second knife — routing sludge to farmland is the exact act being litigated (Maine farms, the Johnson County, Texas suits against a biosolids applier), and PFAS is being excluded from environmental liability policies, so an unbonded intermediary is uninsurable in the one transaction it exists to broker. Landfills are also closing to sludge over leachate PFAS, so the 'outlet' inventory being brokered is shrinking rather than expanding.
A6: 5 | B6: Reachability-grade SBOMs and kernel-CVE triage for embedded Linux | C6: Regulatory clock | D6: cra-embedded-sbom-and-cve-triage | E6: Recall-only | F6: 3 | G6: 8 | H6: 6 | I6: 7 | J6: 6 | K6: =ROUND(F6*Overview!$B$24+G6*Overview!$B$25+H6*Overview!$B$26+I6*Overview!$B$27+J6*Overview!$B$28,2) | L6: Ingest a Yocto/Buildroot/PetaLinux build or raw firmware, emit an SBOM scoring clean against BSI TR-03183-2, index reachability from the kernel .config and driver set, and run it daily against the kernel CNA feed to produce ranked affects-you/does-not lists with OpenVEX justifications. | M6: The recurring pain is correctly located — the CRA's expensive cost is not writing an SBOM, it is deciding weekly whether this week's CVEs reach a shipped device and proving it to a market surveillance authority. Technical why_now verified: the Linux kernel CNA floods ~50 unscored CVEs/week and LTS support contracted from six years to two, while Art. 14 reporting starts 11 Sep 2026 on products already on the market and full CE marking lands 11 Dec 2027. This is a maintenance-contract shape, not a one-time audit, which is the right revenue geometry. Drags that keep it at 5: distribution belongs to whoever ships the BSP — Timesys Vigiles (now Lynx) does config-aware kernel CVE triage today and Qualcomm/Foundries.io bundles continuous remediation with the subscription the customer already buys — and the 90-day two-person plan badly understates binary SBOM extraction plus .config reachability indexing at defensible quality. | N6: Distribution is owned by whoever already ships the BSP. The SoC vendor, Timesys/Lynx, Wind River or Qualcomm/Foundries bundles CVE triage with the board support package the customer is already paying for, so you are selling an add-on against something included. The 90-day two-person plan also badly understates the work — kernel .config reachability indexing plus SBOM extraction from raw firmware binaries is a multi-year engineering problem to do at defensible quality, not a quarter. And the VEX justification you emit is a legal assertion the customer must sign; if a market surveillance authority rejects 'subsystem not compiled in,' your core output is worthless. | O6: Not selected for verification
A7: 6 | B7: Funded-Claim Detection for Casualty Reserving | C7: Boring vertical | D7: funded-claim-detection-for-casualty | E7: Search-backed | F7: 6 | G7: 6 | H7: 6 | I7: 5 | J7: 6 | K7: =ROUND(F7*Overview!$B$24+G7*Overview!$B$25+H7*Overview!$B$26+I7*Overview!$B$27+J7*Overview!$B$28,2) | L7: Claim-scoring data utility fusing the newly public litigation-funder registries with docket data, UCC-1 filings, plaintiff-firm network graphs and medical-lien patterns to flag probable funder involvement at first notice of loss. | M7: Survived adversarial verification 1-of-2, and the surviving lens made the point that matters most under a buyer test: the sufferer IS the payer. Carriers and reinsurers absorb adverse development directly, claims analytics and reserving are established budget lines, and social inflation is the single most-cited casualty concern — willingness to pay is not speculative. The raw material genuinely did not exist before 2026 (Georgia's NMLS registration commenced 1 Jan 2026 with 5% beneficial-ownership disclosure; West Virginia, Indiana, Louisiana, Montana all added regimes), and the Law.com 17 Jul 2026 open-records piece supports that no vendor had assembled the list. Held to 6 by two real problems the screener named: consumer pre-settlement advances to individual plaintiffs are generally not UCC-1 perfected, so the cross-join likely resolves firm-level portfolio funding rather than the per-claim signal being sold; and the disclosure wave that creates the data also erodes the need for inference by 2028-29. Sell the quarterly funder-intelligence report first, productize scoring only once linkage is proven. | N7: The thesis is self-cannibalizing. The same disclosure wave that creates the raw material also destroys the need for detection — Georgia, Kansas, Indiana, Louisiana, Montana, West Virginia and Wisconsin already mandate funder-identity disclosure, ISO has approved a Litigation Funding Disclosure Condition endorsement, and S.3826 would federalize it for class actions and MDLs. If disclosure becomes routine by 2028-2029, insurers get funder identity for free and a paid inference product is worth little. Second, the data-linkage claim is weaker than stated: consumer pre-settlement advances to individual plaintiffs are generally not UCC-1 filed (UCC-1s attach to businesses and law-firm portfolio deals), so the 'cross-join UCC-1 to open claims' mechanic likely resolves only firm-level portfolio funding, not per-claim funding at FNOL. Georgia's registry lists funders and their owners, not which cases they funded — the case linkage is the hard, unsolved part and the 90-day plan quietly assumes it. Third, Verisk or Findevor can bolt this on as a feature the moment it looks valuable; neither lacks the docket data or the carrier relationships. | O7: [lens] Litigation-propensity and attorney-involvement scoring at FNOL for casualty claims is an established, funded product category (CLARA Analytics, Charlee.ai, LexisNexis Risk attorney-representation data, Verisk claims analytics), and 'was this claim funded' is an additional attribute inside a model those incumbents already sell to exactly this buyer. Meanwhile every data primitive named as the moat — NMLS bulk registration data, UCC-1 filings, docket data, shell-layer beneficial-ownership resolution — is already a commodity from established vendors. [lens] The trigger is real but it does not produce the product. The registries create a list of FUNDERS and their beneficial owners; they do not create a claim-level linkage, and the entire value proposition is 'flag probable funder involvement at first notice of loss.' The bridge from a funder registry to a specific open claim is the proposed UCC-1 / docket / plaintiff-firm-graph inference, and that bridge is weak where it matters most: consumer legal funding is structured as a non-recourse purchase of case proceeds from an individual plaintiff and is generally not perfected by UCC-1 against that plaintiff, so UCC-1 filings surface law-firm-level portfolio lending, not the per-claim consumer funding that drives casualty severity. At FNOL — before a complaint is even filed and therefore before any docket exists — the signal is thinnest of all, which is precisely the moment the product claims to fire. Second objection: this is not a vacuum. Attorney-involvement and litigation-propensity scoring at FNOL is a mature product category (CLARA Analytics, Charlee.ai, Verisk's claims analytics), and docket/firm-network analytics is owned by Lex Machina, Trellis and Bloomberg Law. 'Funded' is an incremental attribute bolted onto an occupied product slot, not a new one. Third: the Law.com FOIA is offered as 'the clearest proof nobody has productized this,' but NMLS registration records are substantially public via NMLS Consumer Access, so a reporter filing an open-records request for ownership detail evidences a modest gap, not a category-wide absence — and journalists routinely FOIA data that vendors hold but do not publish free.
A8: 7 | B8: Forward exchange for transformer and switchgear production slots | C8: Physical / industrial | D8: grid-equipment-slot-forward-exchange | E8: Search-backed | F8: 7 | G8: 7 | H8: 7 | I8: 7 | J8: 6 | K8: =ROUND(F8*Overview!$B$24+G8*Overview!$B$25+H8*Overview!$B$26+I8*Overview!$B$27+J8*Overview!$B$28,2) | L8: Clearinghouse for orphaned transformer, switchgear and turbine production slots: OEM-confirmed listings, standardized spec templates, escrow, assignment paperwork, and eventually a forward curve on MVA by delivery quarter. | M8: Highest composite in the entire pool (6.88) and I am overriding the both-refuted rule deliberately. Both skeptics self-reported confidence 6, both disclosed they ran ZERO live searches, and both explicitly conceded 'no venue trading forward slots exists — that absence is real.' Their kill is OEM anti-assignment clauses, which is a deal-structure objection rather than a market objection: assignment-with-consent is routine where the substitute buyer is creditworthy and the OEM's slot stays filled at no cost to it, and the business runs perfectly well as a consented-novation brokerage plus price discovery rather than as bearer-instrument trading. The underlying scarcity is not in dispute — 128-week LPT and 144-week GSU lead times are independently verified, capacity is allocated by prepayment, and FERC's 18 June 2026 §206 show-cause orders to all six RTOs (responses due 17 Aug 2026) are confirmed across six law-firm sources. Ranked 7 not 1 because if OEMs systematically refuse consent to capture the spread themselves there is no business at all, engineered-to-order units are less fungible than the spec template assumes, and six of ten evidence URLs are X posts. This is the highest-variance name on the list. | N8: The whole business runs through the OEM's consent. Standard supply agreements carry anti-assignment/anti-delegation clauses and non-refundable staged deposits; once an OEM learns a slot is worth more than the contract price it has every incentive to cancel, keep the deposit and re-sell at market itself rather than let a broker capture the spread. Warranty assignability is separately restricted. Second risk: the phantom-demand premise is contested — SemiAnalysis published 'Stop Saying Half of 2026 US Datacenter Capacity Is Canceled' rebutting exactly the cancellation statistic this thesis rests on, and if hyperscaler demand holds, orphaned slots never accumulate and there is nothing to clear. Third: Anza already runs a new-equipment exchange plus a procurement desk and is one product decision away from listing undelivered slots. Evidence quality is also weak — six of the ten cited URLs are x.com posts. | O8: [lens] The option value in a cancelled slot accrues to the OEM, not to the depositor, so there is nothing for a clearinghouse to clear. Orders with GE Vernova, Hitachi Energy, Siemens Energy, Eaton, Schneider and ABB carry anti-assignment terms requiring manufacturer consent, and in a sold-out market the OEM's dominant strategy is to refuse consent, keep the 10-30% deposit, and resell the slot itself at the new higher price — the OEM order desk the candidate wants to verify listings with is the incumbent that absorbs this. Compounding it, these units are engineered-to-order: the candidate's own standardization fields (kVA, voltage class, impedance, delivery window) understate BIL, tap changers, bushings, cooling class, footprint and test standards, which is precisely why a slot built for one site is often useless to another. And the adjacent brokerage layer that could add forward slots tomorrow is already capitalized — Maddox Industrial Transformer, Solomon Corporation, T&R Electric, Transformer Exchange — while build.inc, cited in the candidate's own evidence, already sells datacenter transformer procurement intelligence. [lens] The shortage is real but the tradable instrument probably is not. A transformer/GSU 'slot' is not a bearer option — OEM purchase orders (GE Vernova, Hitachi Energy, Siemens Energy, Eaton, Schneider, Prolec, Virginia Transformer) carry anti-assignment clauses and cancellation/liquidated-damages schedules, so the slot cannot change hands without OEM consent, and the OEM has every incentive to withhold consent, keep the non-refundable deposit, and resell the slot itself at the current (much higher) price. The OEM order desk is the natural clearinghouse and already captures the entire arbitrage. Second, large power transformers are engineered-to-order (impedance, BIL, bushing arrangement, footprint, noise, seismic); a partially-engineered unit is not fungible across buyers, so the 'standardize on kVA/voltage/impedance' template collapses for exactly the units that are scarcest. Third, the cited FERC trigger is decorative: a co-location/large-load interconnection-study rulemaking changes queue processing, not equipment-contract assignability. Fourth, the double-booking that supposedly creates orphan supply argues the opposite way — holders keep duplicate slots deliberately as insurance and release them only at the point of cancellation, when the OEM keeps the deposit. Fifth, the party with budget (hyperscalers, big utilities) buys via multi-year frame agreements and reserved-capacity prepayments direct with OEMs and has no need of a 2-4% broker; the desperate marginal developer is the one without money.
A9: 8 | B9: Key-state custody for LMS/XMSS firmware signing under CNSA 2.0 | C9: Infrastructure & standards | D9: stateful-hash-signature-key-state-custody | E9: Recall-only | F9: 6 | G9: 5 | H9: 7 | I9: 4 | J9: 6 | K9: =ROUND(F9*Overview!$B$24+G9*Overview!$B$25+H9*Overview!$B$26+I9*Overview!$B$27+J9*Overview!$B$28,2) | L9: Signing API in front of cloud HSMs that allocates monotonic one-time-key indices under a replicated ledger, reserves disjoint HSS/XMSS-MT subtrees per builder so parallel CI can never collide, refuses to sign on ambiguous state, and emits tamper-evident index-usage audit evidence. | M9: The ONLY candidate in round 1 whose overlooked claim survived live verification: 'XMSS LMS hash-based signature' returns exactly three repositories worldwide, all academic or archived, and every one of seven code-search hits for SP 800-208 is a crypto-inventory scanner classifying the algorithm in a lookup table. Nobody ships state management. The distinctive real insight is that CNSA 2.0 mandates stateful LMS/XMSS rather than ML-DSA for firmware signing, which converts code signing into a crash-consistent distributed-state problem where one HSM clone, DR failover or CI rerun permanently destroys a device root of trust — genuinely nasty, genuinely unowned, and exactly the kind of narrow correctness problem two strong engineers can own. Held to 8 by a binary regulatory risk the screener named precisely: NSA has signalled it anticipates permitting stateless ML-DSA for firmware signing in future guidance, and if that lands the entire reason for the company evaporates with no adjacent market to absorb the pivot. The '1 Jan 2027 gate' is a vendor-blog gloss on NSA's timeline, and the dossier's sources contradict each other on the EO number. | N9: NSA has signaled it anticipates permitting stateless ML-DSA for firmware signing in future CNSA 2.0 guidance; if that lands, the catastrophic-state-management problem the entire company exists to solve simply stops being mandatory, and the narrow NSS/DIB buyer base means there is no adjacent market large enough to absorb the pivot. | O9: Not selected for verification
A10: 9 | B10: Copper sunset triage for fire-alarm, elevator and area-of-refuge lines | C10: Physical / industrial | D10: copper-retirement-life-safety-circuits | E10: Recall-only | F10: 6 | G10: 6 | H10: 5 | I10: 5 | J10: 5 | K10: =ROUND(F10*Overview!$B$24+G10*Overview!$B$25+H10*Overview!$B$26+I10*Overview!$B$27+J10*Overview!$B$28,2) | L10: National data layer joining carrier copper-retirement and §214 discontinuance filings to commercial property, elevator permit and fire-inspection records, sold as a per-line compliance registry with sequenced cutover runbooks and inspector-ready documentation. | M10: The most plausible overlooked claim in round 1 at the layer proposed: the hardware and integrator lanes are unambiguously crowded (Ooma AirDial, NAPCO, Telguard, Kings III, Pye-Barker), but the normalized wire-center-to-building blast-radius dataset has no owner, hardware vendors have no incentive to build it and integrators cannot. The trigger is dated and the code obligation is genuinely non-discretionary: the FCC voted 26 March 2026 to streamline retirement, declined to impose any compatibility requirement on replacements, and cut notice from 180 to 90 days — which is not enough time for a facilities manager to inventory, source, install, test and re-inspect NFPA 72 and ASME A17.1 circuits. Held to 9 by a specific technical kill that may be fatal: FCC filings identify wire centers and CLLIs, not addresses, and after number portability you cannot reliably map a phone number to a serving wire center without licensed LERG/porting data, so the free 'is my building in the blast radius' checker that drives the whole funnel may not be deliverable at the promised fidelity. Test that join in week one. | N10: The core data join may not be buildable as described — FCC filings identify wire centers/CLLIs, not addresses, and after number portability you cannot reliably map a phone number to a serving wire center without licensed LERG/porting data, so the free 'is my building in the blast radius' checker that drives the whole funnel likely cannot be delivered at the promised fidelity. | O10: Not selected for verification
A11: 10 | B11: CUI determination and marking for small defense machine shops | C11: Regulatory clock | D11: cui-determination-for-machine-shops | E11: Search-backed | F11: 6 | G11: 7 | H11: 7 | I11: 5 | J11: 4 | K11: =ROUND(F11*Overview!$B$24+G11*Overview!$B$25+H11*Overview!$B$26+I11*Overview!$B$27+J11*Overview!$B$28,2) | L11: Engine that ingests customer drawings and PDFs, reads DoD distribution statements and DFARS flow-down clauses, decides CUI vs FCI vs neither, applies markings, and emits shop-floor labels plus a defensible audit trail — sold through CMMC consultancies at scoping. | M11: Both skeptics refuted this, and I am retaining it with a rebuttal. Neither ran a live search; both attacked demand and legality rather than the screener's live-verified finding that four differently-worded searches surfaced no product doing this. Their strongest objection — CUI designation is a government function under 32 CFR 2002 and DoDI 5200.48 — is legally true and practically beside the point: unmarked flow-down is precisely the documented pain, which is why Totem publishes a CUI Identification Guide aimed at exactly this buyer and why consultancies bill scoping workshops as a named SKU. Their fallback, 'just treat everything as CUI,' is not free — it drags the entire shop into the GCC High enclave, and enclave seat cost is the very expense scoping reduces. The trigger is the cleanest in round 2 and has not slipped: 48 CFR CMMC published 10 Sep 2025, effective 10 Nov 2025, Phase 2 third-party Level 2 ramp from ~Nov 2026 across tens of thousands of small shops. Ranked 10 because the real risk is channel conflict — you are asking consultancies to resell a tool that deletes their most-billed hour — plus Purview auto-labeling already sitting paid-for in every GCC High tenant. | N11: why_now verified and holds: 48 CFR CMMC final rule published in the Federal Register 10 Sep 2025, Phase 1 effective 10 Nov 2025, DFARS 252.204-7021 now in new solicitations, Phase 2 third-party Level 2 ramp from ~Nov 2026. Real risks are commercial, not factual. (1) Channel conflict: CUI scoping is the most-billed hour in a consultancy's engagement — a tool that automates it cannibalizes the reseller's own revenue, so 'they will resell it' is the weakest link in the thesis. (2) Liability: a shop will not accept an automated CUI determination without a human attestation, so the product degrades into a workpaper generator with consultant sign-off, compressing price. (3) One-time purchase shape — scoping happens at engagement start, not monthly, so recurring revenue is unproven. (4) Microsoft Purview is already paid-for in every GCC High seat and is the path of least resistance for the MSP channel. (5) Small ACV against a long tail of 30-person shops facing $20k-$100k total compliance cost, most of which goes to the enclave, not to determination. | O11: [lens] Data classification and auto-labeling is one of the most crowded categories in enterprise security, and the CUI-specific slice is explicitly productized: Microsoft Purview sensitivity labels plus trainable classifiers ship inside the GCC High tenant that every CMMC enclave vendor already deploys, so the incumbent does not need to 'add this next quarter' — it is bundled in the thing the shop is already buying. Dedicated CUI marking products exist (Fortra's Titus and Boldon James, Janusnet/janusSEAL, all long-standing defense-marking tools), as does CUI discovery marketing from Varonis, Concentric AI and BigID. On the compliance side, CUI scoping and data-flow mapping is a standard billed line item in every CMMC readiness engagement and appears in the CMMC platforms themselves (FutureFeed, Totem Technologies, Kiteworks, PreVeil, Summit 7, Steel Root, Cuick Trac, Exostar, Ignyte). 'Parse distribution statements out of PDF and CAD title blocks' is a feature, not a company. [lens] The trigger is genuinely solid — this is the one date in the batch I can independently confirm — but the product sits on the wrong side of a legal boundary and loses to a free workaround. Under 32 CFR Part 2002 and DoDI 5200.48, CUI designation is a GOVERNMENT function: the requiring activity/contracting officer identifies and marks CUI in the contract; a contractor is not an authorized designating official. A tool that 'decides CUI vs FCI vs neither' therefore sells an unauthorized determination that increases the shop's and the reselling consultant's liability rather than reducing it. In practice the dominant strategy — free, instant and defensible at assessment — is 'treat everything a DoD prime sends us as CUI and keep it in the enclave,' which is exactly what the enclave vendors already sell and which makes per-document classification moot. Where classification is genuinely wanted, it is already bundled: Microsoft Purview sensitivity labels, auto-labeling and trainable classifiers ship inside the GCC High E5 licensing these shops are already forced to buy, and Fortra/Titus, Janusnet, PreVeil and Kiteworks all address CUI handling. The channel is also misaligned: the record's own pitch is that this automates 'the most-billed and least-automated hour' in a consultancy's scoping engagement — consultancies bill hours, so you are asking them to resell a product that deletes their revenue. And the buyer is the most price-resistant in the defense base: a 30-person shop already facing $20-100k of CMMC cost, with a well-documented pattern of small shops exiting the DoD supply chain instead of paying.
A12: 11 | B12: State packaging EPR reporting for mid-market brands | C12: Regulatory clock | D12: rec-state-packaging-epr-reporting-for-mid-market-brands | E12: Thin | F12: 5 | G12: 7 | H12: 8 | I12: 5 | J12: 6 | K12: =ROUND(F12*Overview!$B$24+G12*Overview!$B$25+H12*Overview!$B$26+I12*Overview!$B$27+J12*Overview!$B$28,2) | L12: Physically weigh and characterize every SKU's packaging for a 50-500 SKU food or consumer brand, build the per-SKU material bill of materials, and file the differently-shaped producer report into each state's PRO on its own statutory calendar. | M12: Both skeptics refuted, and again I am retaining with a rebuttal, because both refutations were explicit recall-only with no live search and neither named a company whose ICP is the 50-500 SKU brand doing physical package characterization as a service. Lorax EPI and Ecoveritas are enterprise/EU compliance houses; Specright sells packaging spec management, not state EPR filings; Circular Action Alliance's portal is a submission surface, not the data assembly that feeds it. What survives is the strongest structural feature in the batch: a stacking multi-state calendar (Oregon live 1 Jul 2025, Colorado in fee assessment, Minnesota and Maryland phasing through 2026-2028, Washington enacted 2025) against the same underlying SKU dataset, producing genuine multi-state switching cost and a proprietary physical asset. Ranked 11 rather than higher because California SB 54's 2025 regulatory restart is real and delays the largest single market — proving these deadlines are politically soft — because de minimis exemptions carve out much of the long tail, and because weigh-and-characterize is real opex that caps gross margin. Re-run crowding on Specright, Lorax EPI and Reclay with live search before committing capital. | N12: The why_now largely holds: Oregon's Recycling Modernization Act program went live July 1 2025 with producer reporting, Colorado's program moved to fee assessment in 2025-2026, Minnesota (2024 law) and Maryland (2025) are phasing registration and reporting through 2026-2028, and Washington enacted its EPR law in 2025 — with Circular Action Alliance as PRO across the set, so the 'same SKU data, differently shaped report per state' wedge is real. The notable wobble is California: CalRecycle's SB 54 regulations were withdrawn and restarted in 2025 at the Governor's direction, delaying the largest single market — so a plan that leads with California revenue is mistimed, and further state-level delay or fee-structure softening under industry lobbying is the main risk. Secondary risks: PRO-provided portals plus co-packer-supplied spec sheets could commoditize the filing layer; the physical weigh-and-characterize step is real moat but is also real opex that caps gross margin and slows onboarding; and a $10-25k first-year price into a brand that has never had a packaging engineer is a hard first sale. Advancing on the strength of a verified stacking regulatory calendar, a proprietary dataset that demonstrably does not exist elsewhere, genuine multi-state switching cost, and a 90-day shippable manual wedge — conditional on re-running crowding checks on Specright, Lorax EPI and Reclay StewardEdge with live search. | O12: [lens] Packaging EPR reporting is a mature, 25-year-old European service industry whose vendors have been actively porting to US state programs since the CA/OR/CO/MN/MD laws passed — Ecoveritas and Valpak (both Reconomy), Lorax EPI (whose entire product is multi-jurisdiction packaging EPR data management and fee calculation), Reclay, and Trayak (EcoImpact-COMPASS, packaging LCA plus eco-modulated fee modeling aimed at exactly mid-market CPG). The candidate's claimed moat — 'per-SKU packaging bill-of-materials data doesn't exist anywhere' — is the product definition of Specright, a well-funded packaging specification data platform selling to food and CPG brands, and is also held by every co-packer and packaging converter in spec sheets. The PRO itself (Circular Action Alliance) supplies the reporting portal, templates and calendar across the covered states, which flattens much of the 'differently-shaped report per state' complexity the wedge depends on. [lens] Thinnest evidence base of the six and a wrong core premise. The record is self-labelled '[UNVERIFIED — no live web access this session]', its why_now contains no date at all and instead instructs the reader to 'verify current deadlines per state and Circular Action Alliance's reporting calendar,' and its entire evidence base is three organization homepages (calrecycle.ca.gov, oregon.gov/deq, circularaction.org) with zero captured quotes. Under a demand-and-trigger lens that is an unverified assertion, not a trigger. Substantively: (1) the flagship deadline has slipped — Newsom rejected CalRecycle's SB 54 regulations in March 2025 and ordered the rulemaking restarted, pushing California obligations right and proving this category's deadlines are politically soft; (2) the 'moat' premise is false — brands do not need to weigh their own cartons, because packaging converters and co-packers (WestRock, Amcor, Berry, Sealed Air, Graphic Packaging) supply unit weights and material composition on the spec sheet that accompanies every PO, and Specright already sells packaging-spec/BOM as a system of record to exactly this customer; (3) the field is crowded, not empty — Lorax EPI, Ecoveritas, Reverse Logistics Group, Trayak (EcoImpact-COMPASS, which added EPR fee modelling), Source Intelligence/Assent and consultancies (RRS, Eunomia, Anthesis, ERM) all sell packaging-EPR data assembly and filing, and Circular Action Alliance itself supplies the reporting portal, material category taxonomy and templates as part of the fee — a free substitute bundled with the obligation; (4) de minimis exemptions (roughly <$5M revenue in OR/CO, <$1M CA, plus tonnage floors) carve out much of the long tail the thesis counts on; (5) the eco-modulated fee itself is the dominant cost, so brands optimize spend toward fee reduction, not toward a $10-25k data-assembly engagement.
A13: 12 | B13: Part 146 ADSP certification: strategic deconfliction plus the sub-400-foot obstacle layer | C13: Infrastructure & standards | D13: part-146-bvlos-data-services | E13: Recall-only | F13: 5 | G13: 7 | H13: 5 | I13: 6 | J13: 7 | K13: =ROUND(F13*Overview!$B$24+G13*Overview!$B$25+H13*Overview!$B$26+I13*Overview!$B$27+J13*Overview!$B$28,2) | L13: Become a certificated Automated Data Service Provider in the near-empty supplemental-data lane by building the survey-grade, continuously refreshed national database of sub-400-foot obstacles — distribution lines, guy wires, met towers, cranes — that existing FAA obstacle data does not resolve. | M13: A federally certificated toll position on US low-altitude airspace with no established winner is a rare structural prize, and the strategic read is correct: visible entrants are all racing at deconfliction because it is the glamorous algorithmic part, leaving supplemental data thinner. The regulatory creation of the category is verified — the FAA BVLOS NPRM published Aug 2025 with proposed Part 146 following the June 2025 executive order, and the final rule reached OIRA 10 July 2026. Ranked 12 because the timing risk is severe and structural: BVLOS has slipped for a decade, the candidate's own revenue curve is 2028-2031 which sits entirely beyond a seed runway, and you would burn three years selling obstacle data into utility inspection budgets against Neara (~$45M) and AiDash (~$58M), who already exploit utility LiDAR and already sit inside those accounts. Second risk: the final rule may permit deconfliction ADSPs to self-supply data, collapsing the separate SDS market the whole thesis needs. | N13: Timing. BVLOS has slipped for a decade and the revenue curve the candidate itself puts at 2028-2031 sits entirely beyond a seed runway; if the final rule lands in 2027 and certification takes 18 months, you burn three years selling obstacle data into utility inspection budgets against Neara and AiDash, who are better capitalized and already inside those accounts. Secondary risk: the final rule may let deconfliction ADSPs self-supply data, collapsing the separate SDS market the whole thesis depends on. | O13: Not selected for verification
... A26: 25 | B26: Killing lead-line 'unknowns' before the Nov 1, 2027 LCRI baseline locks in | C26: Regulatory clock | D26: lead-service-line-inventory-2027 | E26: Recall-only | F26: 2 | G26: 6 | H26: 6 | I26: 5 | J26: 3 | K26: =ROUND(F26*Overview!$B$24+G26*Overview!$B$25+H26*Overview!$B$26+I26*Overview!$B$27+J26*Overview!$B$28,2) | L26: Drive the 'unknown' count toward zero before the LCRI baseline inventory locks on 1 November 2027, since unknowns are treated as lead and the baseline fixes each system's mandatory replacement rate for years. | M26: Included at 25 on the strength of one genuinely sharp mechanical insight: unknowns are deemed lead, and the 1 Nov 2027 baseline locks in a mandatory replacement rate, so every unknown resolved before that date removes capital obligation permanently — a rare case where diagnostic work has a directly computable dollar value to the buyer. Ranked last because the monetization design fails on public-procurement mechanics the screener identified correctly: municipalities cannot pay a contingency fee out of capital they merely avoided spending, so the outcome-priced model is largely uncontractable and the business collapses back into hourly engineering already performed by incumbent firms, with 120Water, BlueConduit and Trinnex holding the software layer and free federally-funded technical assistance anchoring price. The LCRI compliance date also sat under active litigation and EPA reconsideration, so even the date is not firm. | N26: The outcome-priced 'share of avoided replacement obligation' model is largely uncontractable in public procurement — municipalities cannot pay a contingency fee out of capital they merely avoided spending — so the business collapses back into hourly engineering work already done by incumbent firms. | O26: Not selected for verification

Sheet All Opportunities
A1: ID | B1: Opportunity | C1: In top 25? | D1: Rank | E1: Evidence | F1: Composite | G1: Verdict | H1: Thesis | I1: Why now | J1: Why overlooked | K1: The 90-day wedge | L1: Discovery lens | M1: Sources
A2: datacenter-as-grid-entity-compliance | B2: Ride-through models and curtailment proof for NERC-registered data centers | C2: Yes | D2: 1 | E2: Recall-only | F2: =IFERROR(INDEX('Screening Scores'!$I:$I,MATCH($A2,'Screening Scores'!$A:$A,0)),"") | G2: advance | H2: Data centers are becoming NERC-registered reliability entities with generator-like performance obligations, and almost nobody can do the engineering or produce the evidence. The business is a boutique that builds the filed dynamic model (EPRI UDM for the power-electronic portion, CMLD for cooling), runs disturbance-response testing of UPS transfer thresholds, rectifier and chiller settings, designs remediation, and assembles the attestation package — repeated per campus, per interconnection, per ISO, at roughly $150k-$600k a campus with mandatory re-validation after every trip event. Bolted onto that is the flexibility half: ERCOT's Provisional Controllable Load Resource construct splits a load into a firm portion and a SCED-dispatched flexible portion, and nobody sells the registration filings, penalty-exposure tracking, or the signed, timestamped metering record that proves each curtailment instruction was actually honored. Buyers are large-load customers (data center developers, electrolyzers, crypto) and the utilities that must administer these agreements; whoever owns the measurement and verification record owns the settlement. | I2: Four dated triggers have already fired. NERC issued a Level 3 Essential Actions Alert on 4 May 2026 — only the third in its 58-year history — with entity responses due 3 August 2026. FERC issued an order in Docket RD26-7-000 on 16 July 2026 directing NERC to file mandatory reliability standards for computational loads by 31 December 2026 and a Phase II work plan by 1 March 2027. FERC issued tailored Section 206 orders to every RTO on 18 June 2026 (Docket RM26-4) to accelerate large-load interconnection. ERCOT's NOGRR 282 grandfathers only facilities energized or study-complete on or before 14 November 2025 and imposes a 90-day root-cause / 90-day corrective-plan / 180-day implementation cycle after any failed ride-through. ERCOT is tracking more than 438 GW of large-load requests with roughly 198 GW applying in Q1 2026 alone, nearly 90% data centers — every one of which will need a filed, defensible model and a performance record by 2029-2031. | J2: The entire 'data center power' startup wave aimed at generation, siting and physical flexing (Emerald AI, VoltaGrid, Verrus, Build.inc), and the adjacent software money went to generator interconnection queue automation (Google/Tapestry HyperQ with PJM, Enverus SUGAR with MISO). Neither touches the load-side reliability-compliance obligation or the paperwork-and-proof layer that decides whether a curtailable interconnection agreement is granted, honored and paid for. Today that work sits with a handful of tiny consultancies (EPE Consulting, Keentel Engineering) and hyperscaler internal EE teams that have never filed a NERC-facing dynamic model; large-load interconnection is so new as a formal construct that incumbent transmission-planning software does not model it and consulting engineers do it by hand. NERC's own Large Loads Task Force white papers (Jul 2025, Mar 2026) describe this as a gap in existing practices and Reliability Standards. | K2: Two power-systems engineers with PSS/E and PSCAD licenses and EPRI UDM familiarity, starting in ERCOT where the construct is furthest along. 90 days: publish a free 'NOGRR 282 / NERC Level 3 Alert readiness gap assessment' aimed specifically at ERCOT large loads that are NOT grandfathered (energized after 14 November 2025), then convert to the paid dynamic model build plus UPS transfer-threshold study — field data collects off existing PQ meters at the point of interconnection, and the scarce input is the person who can translate IEC 62040-3 UPS transfer behavior into an ISO-acceptable load model. Second product, sold to the same three data center developers already paying consultancies per filing: the PCLR/Batch Zero registration and modeling data pack (PGRR145 artifacts, ride-through documentation, self-limiting control descriptions) as guided software, plus a metering pipeline that emits a signed, timestamped curtailment performance record against each dispatch instruction. | L2: Physical world — industry, energy, grid, water, logistics, materials, construction; Revealed enterprise demand — what large organizations are actively trying to buy or staff for | M2: https://www.powermag.com/ferc-orders-mandatory-nerc-reliability-standards-for-data-center-and-other-computational-loads/ https://www.nerc.com/newsroom/ferc-sets-year-end-deadline-for-nerc-to-finalize-registry-criteria-and-standards-for-computational-loads https://www.rtoinsider.com/136792-ferc-directs-large-loads-standards-by-end-of-2026/ https://www.ercot.com/files/docs/2026/03/02/04_LEL-RT-Requirements_SPWG_Feb2026.pdf https://epeconsulting.com/epe-intelligence/news/preparing-for-nogrr-282-ercot-s-next-phase-of-large-load-requirements https://www.utilitydive.com/news/data-center-load-disruptions-nerc-alert-recommendations/818036/ https://www.latitudemedia.com/news/as-more-data-center-trip-off-the-grid-ride-through-rules-gain-steam/ https://www.nerc.com/globalassets/who-we-are/standing-committees/rstc/whitepaper-characteristics-and-risks-of-emerging-large-loads.pdf https://www.utilitydive.com/news/texas-facing-438-gw-queue-approves-initial-large-load-interconnection-pro/823367/ https://www.ferc.gov/rm26-4 https://www.ercot.com/services/rq/large-load-integration https://www.zeroemissiongrid.com/insights-press-zeg-blog/ercot-large-load-interconnection-2026/
